Workbook
Name L_Chantiers: '10 Chantiers'!$C$9:$C$38
Name L_Couleur: Listes!$H$2:$H$9
Name L_Equipes: '01 Équipes'!$B$9:$B$38
Name L_Frequence: Listes!$F$2:$F$8
Name L_Fuseau: Listes!$K$2:$K$6
Name L_Instances: '11 Instances'!$B$9:$B$28
Name L_Lots: '07 Lots'!$B$9:$B$38
Name L_Niveau: Listes!$G$2:$G$5
Name L_OuiNon: Listes!$E$2:$E$3
Name L_Permission: Listes!$D$2:$D$6
Name L_Personnes: '03 Personnes'!$B$9:$B$158
Name L_Phases: '08 Phases'!$B$9:$B$38
Name L_RoleInstance: Listes!$I$2:$I$5
Name L_Roles: '02 Rôles'!$B$9:$B$48
Name L_Rubriques: Listes!$L$2:$L$9
Name L_RubriquesPaires: Listes!$M$2:$M$4
Name L_SousPhases: '09 Sous-phases'!$B$9:$B$88
Name L_StatutChantier: Listes!$C$2:$C$3
Name L_StatutLot: Listes!$A$2:$A$4
Name L_StatutPhase: Listes!$B$2:$B$4
Name L_StatutProjet: Listes!$J$2:$J$4

Sheet Complétude
B2: Référentiel projet
B3: Fichier d’initialisation · à remplir par le PMO pendant la préparation du projet
B5: =IF(SUM(L17:L34)=0,0,SUM(K17:K34)/SUM(L17:L34)) -> 0 | D5: ="complétude globale · "&SUM(K17:K34)&" / "&SUM(L17:L34)&" champs obligatoires" -> complétude globale · 0 / 46 champs obligatoires
D6: =COUNTIF(J17:J34,"Complet")&" onglets complets sur 14 · "&COUNTIF(J17:J34,"À démarrer")&" à démarrer" -> 0 onglets complets sur 14 · 14 à démarrer
B8: 1 | C8: Remplissez les groupes dans l’ordre (Organisation, Structure, Gouvernance, Pilotage), puis les onglets dans l’ordre des étapes.
B9: 2 | C9: Choisissez les valeurs dans les listes ▾ : elles se nourrissent des onglets précédents et relient les onglets entre eux.
B10: 3 | C10: Une cellule orangée est un champ obligatoire manquant ; la colonne Contrôle signale les incohérences.
C12: OBLIGATOIRE compte dans la complétude FACULTATIF ne compte pas CALCULÉ rempli par le fichier, fond gris ▾ liste reliée à un autre onglet
C14: Champ obligatoire manquant | D14: ⚠ incohérence bloquante ◔ avertissement
B16: Étape | C16: Onglet | D16: Contenu | E16: Dépend de | F16: Lignes | G16: Obligatoires remplis | H16: Progression | I16: % | J16: Statut
C17: ORGANISATION
B18: 01 | C18: Équipes | D18: Sociétés et entités du projet | E18: — | F18: =SUMPRODUCT(((('01 Équipes'!$B$9:$B$38<>"")+('01 Équipes'!$C$9:$C$38<>""))>0)*1) -> 0 | G18: =K18&" / "&L18 -> 0 / 1 | H18: =REPT("━",ROUND(I18*12,0)) | I18: =K18/L18 -> 0 | J18: =IF(I18>=1,"Complet",IF(K18=0,"À démarrer","En cours")) -> À démarrer | K18: =SUMPRODUCT(((('01 Équipes'!$B$9:$B$38<>"")+('01 Équipes'!$C$9:$C$38<>""))>0)*('01 Équipes'!$B$9:$B$38<>"")) -> 0 | L18: =MAX(1,F18)*1 -> 1
B19: 02 | C19: Rôles projet | D19: Rôles métier | E19: — | F19: =SUMPRODUCT(((('02 Rôles'!$B$9:$B$48<>"")+('02 Rôles'!$C$9:$C$48<>""))>0)*1) -> 0 | G19: =K19&" / "&L19 -> 0 / 1 | H19: =REPT("━",ROUND(I19*12,0)) | I19: =K19/L19 -> 0 | J19: =IF(I19>=1,"Complet",IF(K19=0,"À démarrer","En cours")) -> À démarrer | K19: =SUMPRODUCT(((('02 Rôles'!$B$9:$B$48<>"")+('02 Rôles'!$C$9:$C$48<>""))>0)*('02 Rôles'!$B$9:$B$48<>"")) -> 0 | L19: =MAX(1,F19)*1 -> 1
B20: 03 | C20: Personnes | D20: Annuaire du projet | E20: Équipes | F20: =SUMPRODUCT(((('03 Personnes'!$B$9:$B$158<>"")+('03 Personnes'!$C$9:$C$158<>"")+('03 Personnes'!$D$9:$D$158<>"")+('03 Personnes'!$E$9:$E$158<>"")+('03 Personnes'!$F$9:$F$158<>"")+('03 Personnes'!$G$9:$G$158<>""))>0)*1) -> 0 | G20: =K20&" / "&L20 -> 0 / 4 | H20: =REPT("━",ROUND(I20*12,0)) | I20: =K20/L20 -> 0 | J20: =IF(I20>=1,"Complet",IF(K20=0,"À démarrer","En cours")) -> À démarrer | K20: =SUMPRODUCT(((('03 Personnes'!$B$9:$B$158<>"")+('03 Personnes'!$C$9:$C$158<>"")+('03 Personnes'!$D$9:$D$158<>"")+('03 Personnes'!$E$9:$E$158<>"")+('03 Personnes'!$F$9:$F$158<>"")+('03 Personnes'!$G$9:$G$158<>""))>0)*('03 Personnes'!$B$9:$B$158<>""))+SUMPRODUCT(((('03 Personnes'!$B$9:$B$158<>"")+('03 Personnes'!$C$9:$C$158<>"")+('03 Personnes'!$D$9:$D$158<>"")+('03 Personnes'!$E$9:$E$158<>"")+('03 Personnes'!$F$9:$F$158<>"")+('03 Personnes'!$G$9:$G$158<>""))>0)*('03 Personnes'!$C$9:$C$158<>""))+SUMPRODUCT(((('03 Personnes'!$B$9:$B$158<>"")+('03 Personnes'!$C$9:$C$158<>"")+('03 Personnes'!$D$9:$D$158<>"")+('03 Personnes'!$E$9:$E$158<>"")+('03 Personnes'!$F$9:$F$158<>"")+('03 Personnes'!$G$9:$G$158<>""))>0)*('03 Personnes'!$D$9:$D$158<>""))+SUMPRODUCT(((('03 Personnes'!$B$9:$B$158<>"")+('03 Personnes'!$C$9:$C$158<>"")+('03 Personnes'!$D$9:$D$158<>"")+('03 Personnes'!$E$9:$E$158<>"")+('03 Personnes'!$F$9:$F$158<>"")+('03 Personnes'!$G$9:$G$158<>""))>0)*('03 Personnes'!$F$9:$F$158<>"")) -> 0 | L20: =MAX(1,F20)*4 -> 4
B21: 04 | C21: Affectations | D21: Qui tient quel rôle, et quand | E21: Personnes, Rôles | F21: =SUMPRODUCT(((('04 Affectations'!$B$9:$B$208<>"")+('04 Affectations'!$C$9:$C$208<>"")+('04 Affectations'!$E$9:$E$208<>"")+('04 Affectations'!$F$9:$F$208<>""))>0)*1) -> 0 | G21: =K21&" / "&L21 -> 0 / 3 | H21: =REPT("━",ROUND(I21*12,0)) | I21: =K21/L21 -> 0 | J21: =IF(I21>=1,"Complet",IF(K21=0,"À démarrer","En cours")) -> À démarrer | K21: =SUMPRODUCT(((('04 Affectations'!$B$9:$B$208<>"")+('04 Affectations'!$C$9:$C$208<>"")+('04 Affectations'!$E$9:$E$208<>"")+('04 Affectations'!$F$9:$F$208<>""))>0)*('04 Affectations'!$B$9:$B$208<>""))+SUMPRODUCT(((('04 Affectations'!$B$9:$B$208<>"")+('04 Affectations'!$C$9:$C$208<>"")+('04 Affectations'!$E$9:$E$208<>"")+('04 Affectations'!$F$9:$F$208<>""))>0)*('04 Affectations'!$C$9:$C$208<>""))+SUMPRODUCT(((('04 Affectations'!$B$9:$B$208<>"")+('04 Affectations'!$C$9:$C$208<>"")+('04 Affectations'!$E$9:$E$208<>"")+('04 Affectations'!$F$9:$F$208<>""))>0)*('04 Affectations'!$E$9:$E$208<>"")) -> 0 | L21: =MAX(1,F21)*3 -> 3
C22: STRUCTURE
B23: 05 | C23: Projet | D23: Identité du client et du projet | E23: Équipes, Personnes | F23: — | G23: =K23&" / "&L23 -> 0 / 8 | H23: =REPT("━",ROUND(I23*12,0)) | I23: =K23/L23 -> 0 | J23: =IF(I23>=1,"Complet",IF(K23=0,"À démarrer","En cours")) -> À démarrer | K23: =('05 Projet'!D8<>"")+('05 Projet'!D10<>"")+('05 Projet'!D14<>"")+('05 Projet'!D15<>"")+('05 Projet'!D19<>"")+('05 Projet'!D20<>"")+('05 Projet'!D21<>"")+('05 Projet'!D23<>"") -> 0 | L23: =8 -> 8
B24: 06 | C24: Info projet | D24: Contexte client et périmètre | E24: Projet | F24: =SUMPRODUCT(((('06 Info projet'!$B$9:$B$128<>"")+('06 Info projet'!$C$9:$C$128<>"")+('06 Info projet'!$D$9:$D$128<>""))>0)*1) -> 0 | G24: =K24&" / "&L24 -> 0 / 2 | H24: =REPT("━",ROUND(I24*12,0)) | I24: =K24/L24 -> 0 | J24: =IF(I24>=1,"Complet",IF(K24=0,"À démarrer","En cours")) -> À démarrer | K24: =(COUNTIFS('06 Info projet'!$B$9:$B$128,"Programme en une phrase",'06 Info projet'!$D$9:$D$128,"<>")>0)+(COUNTIFS('06 Info projet'!$B$9:$B$128,"Enjeux stratégiques",'06 Info projet'!$D$9:$D$128,"<>")>0) -> 0 | L24: =2 -> 2
B25: 07 | C25: Lots | D25: Vagues de déploiement | E25: Personnes | F25: =SUMPRODUCT(((('07 Lots'!$C$9:$C$38<>"")+('07 Lots'!$D$9:$D$38<>"")+('07 Lots'!$E$9:$E$38<>"")+('07 Lots'!$F$9:$F$38<>"")+('07 Lots'!$G$9:$G$38<>"")+('07 Lots'!$H$9:$H$38<>""))>0)*1) -> 0 | G25: =K25&" / "&L25 -> 0 / 4 | H25: =REPT("━",ROUND(I25*12,0)) | I25: =K25/L25 -> 0 | J25: =IF(I25>=1,"Complet",IF(K25=0,"À démarrer","En cours")) -> À démarrer | K25: =SUMPRODUCT(((('07 Lots'!$C$9:$C$38<>"")+('07 Lots'!$D$9:$D$38<>"")+('07 Lots'!$E$9:$E$38<>"")+('07 Lots'!$F$9:$F$38<>"")+('07 Lots'!$G$9:$G$38<>"")+('07 Lots'!$H$9:$H$38<>""))>0)*('07 Lots'!$C$9:$C$38<>""))+SUMPRODUCT(((('07 Lots'!$C$9:$C$38<>"")+('07 Lots'!$D$9:$D$38<>"")+('07 Lots'!$E$9:$E$38<>"")+('07 Lots'!$F$9:$F$38<>"")+('07 Lots'!$G$9:$G$38<>"")+('07 Lots'!$H$9:$H$38<>""))>0)*('07 Lots'!$D$9:$D$38<>""))+SUMPRODUCT(((('07 Lots'!$C$9:$C$38<>"")+('07 Lots'!$D$9:$D$38<>"")+('07 Lots'!$E$9:$E$38<>"")+('07 Lots'!$F$9:$F$38<>"")+('07 Lots'!$G$9:$G$38<>"")+('07 Lots'!$H$9:$H$38<>""))>0)*('07 Lots'!$E$9:$E$38<>""))+SUMPRODUCT(((('07 Lots'!$C$9:$C$38<>"")+('07 Lots'!$D$9:$D$38<>"")+('07 Lots'!$E$9:$E$38<>"")+('07 Lots'!$F$9:$F$38<>"")+('07 Lots'!$G$9:$G$38<>"")+('07 Lots'!$H$9:$H$38<>""))>0)*('07 Lots'!$F$9:$F$38<>"")) -> 0 | L25: =MAX(1,F25)*4 -> 4
B26: 08 | C26: Phases | D26: Grandes étapes de la méthode | E26: Lots | F26: =SUMPRODUCT(((('08 Phases'!$C$9:$C$38<>"")+('08 Phases'!$D$9:$D$38<>"")+('08 Phases'!$E$9:$E$38<>"")+('08 Phases'!$F$9:$F$38<>"")+('08 Phases'!$G$9:$G$38<>"")+('08 Phases'!$H$9:$H$38<>"")+('08 Phases'!$I$9:$I$38<>""))>0)*1) -> 0 | G26: =K26&" / "&L26 -> 0 / 5 | H26: =REPT("━",ROUND(I26*12,0)) | I26: =K26/L26 -> 0 | J26: =IF(I26>=1,"Complet",IF(K26=0,"À démarrer","En cours")) -> À démarrer | K26: =SUMPRODUCT(((('08 Phases'!$C$9:$C$38<>"")+('08 Phases'!$D$9:$D$38<>"")+('08 Phases'!$E$9:$E$38<>"")+('08 Phases'!$F$9:$F$38<>"")+('08 Phases'!$G$9:$G$38<>"")+('08 Phases'!$H$9:$H$38<>"")+('08 Phases'!$I$9:$I$38<>""))>0)*('08 Phases'!$C$9:$C$38<>""))+SUMPRODUCT(((('08 Phases'!$C$9:$C$38<>"")+('08 Phases'!$D$9:$D$38<>"")+('08 Phases'!$E$9:$E$38<>"")+('08 Phases'!$F$9:$F$38<>"")+('08 Phases'!$G$9:$G$38<>"")+('08 Phases'!$H$9:$H$38<>"")+('08 Phases'!$I$9:$I$38<>""))>0)*('08 Phases'!$D$9:$D$38<>""))+SUMPRODUCT(((('08 Phases'!$C$9:$C$38<>"")+('08 Phases'!$D$9:$D$38<>"")+('08 Phases'!$E$9:$E$38<>"")+('08 Phases'!$F$9:$F$38<>"")+('08 Phases'!$G$9:$G$38<>"")+('08 Phases'!$H$9:$H$38<>"")+('08 Phases'!$I$9:$I$38<>""))>0)*('08 Phases'!$E$9:$E$38<>""))+SUMPRODUCT(((('08 Phases'!$C$9:$C$38<>"")+('08 Phases'!$D$9:$D$38<>"")+('08 Phases'!$E$9:$E$38<>"")+('08 Phases'!$F$9:$F$38<>"")+('08 Phases'!$G$9:$G$38<>"")+('08 Phases'!$H$9:$H$38<>"")+('08 Phases'!$I$9:$I$38<>""))>0)*('08 Phases'!$F$9:$F$38<>""))+SUMPRODUCT(((('08 Phases'!$C$9:$C$38<>"")+('08 Phases'!$D$9:$D$38<>"")+('08 Phases'!$E$9:$E$38<>"")+('08 Phases'!$F$9:$F$38<>"")+('08 Phases'!$G$9:$G$38<>"")+('08 Phases'!$H$9:$H$38<>"")+('08 Phases'!$I$9:$I$38<>""))>0)*('08 Phases'!$G$9:$G$38<>"")) -> 0 | L26: =MAX(1,F26)*5 -> 5
B27: 09 | C27: Sous-phases | D27: Découpage des phases | E27: Phases | F27: =SUMPRODUCT(((('09 Sous-phases'!$C$9:$C$88<>"")+('09 Sous-phases'!$D$9:$D$88<>"")+('09 Sous-phases'!$E$9:$E$88<>"")+('09 Sous-phases'!$F$9:$F$88<>"")+('09 Sous-phases'!$G$9:$G$88<>"")+('09 Sous-phases'!$H$9:$H$88<>"")+('09 Sous-phases'!$I$9:$I$88<>""))>0)*1) -> 0 | G27: =K27&" / "&L27 -> 0 / 3 | H27: =REPT("━",ROUND(I27*12,0)) | I27: =K27/L27 -> 0 | J27: =IF(I27>=1,"Complet",IF(K27=0,"À démarrer","En cours")) -> À démarrer | K27: =SUMPRODUCT(((('09 Sous-phases'!$C$9:$C$88<>"")+('09 Sous-phases'!$D$9:$D$88<>"")+('09 Sous-phases'!$E$9:$E$88<>"")+('09 Sous-phases'!$F$9:$F$88<>"")+('09 Sous-phases'!$G$9:$G$88<>"")+('09 Sous-phases'!$H$9:$H$88<>"")+('09 Sous-phases'!$I$9:$I$88<>""))>0)*('09 Sous-phases'!$C$9:$C$88<>""))+SUMPRODUCT(((('09 Sous-phases'!$C$9:$C$88<>"")+('09 Sous-phases'!$D$9:$D$88<>"")+('09 Sous-phases'!$E$9:$E$88<>"")+('09 Sous-phases'!$F$9:$F$88<>"")+('09 Sous-phases'!$G$9:$G$88<>"")+('09 Sous-phases'!$H$9:$H$88<>"")+('09 Sous-phases'!$I$9:$I$88<>""))>0)*('09 Sous-phases'!$D$9:$D$88<>""))+SUMPRODUCT(((('09 Sous-phases'!$C$9:$C$88<>"")+('09 Sous-phases'!$D$9:$D$88<>"")+('09 Sous-phases'!$E$9:$E$88<>"")+('09 Sous-phases'!$F$9:$F$88<>"")+('09 Sous-phases'!$G$9:$G$88<>"")+('09 Sous-phases'!$H$9:$H$88<>"")+('09 Sous-phases'!$I$9:$I$88<>""))>0)*('09 Sous-phases'!$E$9:$E$88<>"")) -> 0 | L27: =MAX(1,F27)*3 -> 3
B28: 10 | C28: Chantiers | D28: Domaines de travail | E28: Personnes, Lots, Phases, Sous-phases | F28: =SUMPRODUCT(((('10 Chantiers'!$C$9:$C$38<>"")+('10 Chantiers'!$D$9:$D$38<>"")+('10 Chantiers'!$E$9:$E$38<>"")+('10 Chantiers'!$F$9:$F$38<>"")+('10 Chantiers'!$I$9:$I$38<>"")+('10 Chantiers'!$J$9:$J$38<>"")+('10 Chantiers'!$K$9:$K$38<>"")+('10 Chantiers'!$L$9:$L$38<>""))>0)*1) -> 0 | G28: =K28&" / "&L28 -> 0 / 2 | H28: =REPT("━",ROUND(I28*12,0)) | I28: =K28/L28 -> 0 | J28: =IF(I28>=1,"Complet",IF(K28=0,"À démarrer","En cours")) -> À démarrer | K28: =SUMPRODUCT(((('10 Chantiers'!$C$9:$C$38<>"")+('10 Chantiers'!$D$9:$D$38<>"")+('10 Chantiers'!$E$9:$E$38<>"")+('10 Chantiers'!$F$9:$F$38<>"")+('10 Chantiers'!$I$9:$I$38<>"")+('10 Chantiers'!$J$9:$J$38<>"")+('10 Chantiers'!$K$9:$K$38<>"")+('10 Chantiers'!$L$9:$L$38<>""))>0)*('10 Chantiers'!$C$9:$C$38<>""))+SUMPRODUCT(((('10 Chantiers'!$C$9:$C$38<>"")+('10 Chantiers'!$D$9:$D$38<>"")+('10 Chantiers'!$E$9:$E$38<>"")+('10 Chantiers'!$F$9:$F$38<>"")+('10 Chantiers'!$I$9:$I$38<>"")+('10 Chantiers'!$J$9:$J$38<>"")+('10 Chantiers'!$K$9:$K$38<>"")+('10 Chantiers'!$L$9:$L$38<>""))>0)*('10 Chantiers'!$D$9:$D$38<>"")) -> 0 | L28: =MAX(1,F28)*2 -> 2
C29: GOUVERNANCE
B30: 11 | C30: Instances de pilotage | D30: Comités du projet | E30: — | F30: =SUMPRODUCT(((('11 Instances'!$B$9:$B$28<>"")+('11 Instances'!$C$9:$C$28<>"")+('11 Instances'!$D$9:$D$28<>"")+('11 Instances'!$F$9:$F$28<>"")+('11 Instances'!$G$9:$G$28<>"")+('11 Instances'!$H$9:$H$28<>""))>0)*1) -> 0 | G30: =K30&" / "&L30 -> 0 / 4 | H30: =REPT("━",ROUND(I30*12,0)) | I30: =K30/L30 -> 0 | J30: =IF(I30>=1,"Complet",IF(K30=0,"À démarrer","En cours")) -> À démarrer | K30: =SUMPRODUCT(((('11 Instances'!$B$9:$B$28<>"")+('11 Instances'!$C$9:$C$28<>"")+('11 Instances'!$D$9:$D$28<>"")+('11 Instances'!$F$9:$F$28<>"")+('11 Instances'!$G$9:$G$28<>"")+('11 Instances'!$H$9:$H$28<>""))>0)*('11 Instances'!$B$9:$B$28<>""))+SUMPRODUCT(((('11 Instances'!$B$9:$B$28<>"")+('11 Instances'!$C$9:$C$28<>"")+('11 Instances'!$D$9:$D$28<>"")+('11 Instances'!$F$9:$F$28<>"")+('11 Instances'!$G$9:$G$28<>"")+('11 Instances'!$H$9:$H$28<>""))>0)*('11 Instances'!$C$9:$C$28<>""))+SUMPRODUCT(((('11 Instances'!$B$9:$B$28<>"")+('11 Instances'!$C$9:$C$28<>"")+('11 Instances'!$D$9:$D$28<>"")+('11 Instances'!$F$9:$F$28<>"")+('11 Instances'!$G$9:$G$28<>"")+('11 Instances'!$H$9:$H$28<>""))>0)*('11 Instances'!$D$9:$D$28<>""))+SUMPRODUCT(((('11 Instances'!$B$9:$B$28<>"")+('11 Instances'!$C$9:$C$28<>"")+('11 Instances'!$D$9:$D$28<>"")+('11 Instances'!$F$9:$F$28<>"")+('11 Instances'!$G$9:$G$28<>"")+('11 Instances'!$H$9:$H$28<>""))>0)*('11 Instances'!$F$9:$F$28<>"")) -> 0 | L30: =MAX(1,F30)*4 -> 4
B31: 12 | C31: Membres des instances | D31: Composition des comités | E31: Instances, Personnes | F31: =SUMPRODUCT(((('12 Membres'!$B$9:$B$208<>"")+('12 Membres'!$C$9:$C$208<>"")+('12 Membres'!$D$9:$D$208<>""))>0)*1) -> 0 | G31: =K31&" / "&L31 -> 0 / 2 | H31: =REPT("━",ROUND(I31*12,0)) | I31: =K31/L31 -> 0 | J31: =IF(I31>=1,"Complet",IF(K31=0,"À démarrer","En cours")) -> À démarrer | K31: =SUMPRODUCT(((('12 Membres'!$B$9:$B$208<>"")+('12 Membres'!$C$9:$C$208<>"")+('12 Membres'!$D$9:$D$208<>""))>0)*('12 Membres'!$B$9:$B$208<>""))+SUMPRODUCT(((('12 Membres'!$B$9:$B$208<>"")+('12 Membres'!$C$9:$C$208<>"")+('12 Membres'!$D$9:$D$208<>""))>0)*('12 Membres'!$C$9:$C$208<>"")) -> 0 | L31: =MAX(1,F31)*2 -> 2
C32: PILOTAGE
B33: 13 | C33: Jalons | D33: Dates clés | E33: Phases, Sous-phases, Chantiers, Lots, Personnes | F33: =SUMPRODUCT(((('13 Jalons'!$C$9:$C$108<>"")+('13 Jalons'!$D$9:$D$108<>"")+('13 Jalons'!$E$9:$E$108<>"")+('13 Jalons'!$F$9:$F$108<>"")+('13 Jalons'!$G$9:$G$108<>"")+('13 Jalons'!$H$9:$H$108<>"")+('13 Jalons'!$I$9:$I$108<>"")+('13 Jalons'!$J$9:$J$108<>""))>0)*1) -> 0 | G33: =K33&" / "&L33 -> 0 / 3 | H33: =REPT("━",ROUND(I33*12,0)) | I33: =K33/L33 -> 0 | J33: =IF(I33>=1,"Complet",IF(K33=0,"À démarrer","En cours")) -> À démarrer | K33: =SUMPRODUCT(((('13 Jalons'!$C$9:$C$108<>"")+('13 Jalons'!$D$9:$D$108<>"")+('13 Jalons'!$E$9:$E$108<>"")+('13 Jalons'!$F$9:$F$108<>"")+('13 Jalons'!$G$9:$G$108<>"")+('13 Jalons'!$H$9:$H$108<>"")+('13 Jalons'!$I$9:$I$108<>"")+('13 Jalons'!$J$9:$J$108<>""))>0)*('13 Jalons'!$C$9:$C$108<>""))+SUMPRODUCT(((('13 Jalons'!$C$9:$C$108<>"")+('13 Jalons'!$D$9:$D$108<>"")+('13 Jalons'!$E$9:$E$108<>"")+('13 Jalons'!$F$9:$F$108<>"")+('13 Jalons'!$G$9:$G$108<>"")+('13 Jalons'!$H$9:$H$108<>"")+('13 Jalons'!$I$9:$I$108<>"")+('13 Jalons'!$J$9:$J$108<>""))>0)*('13 Jalons'!$D$9:$D$108<>""))+SUMPRODUCT(((('13 Jalons'!$C$9:$C$108<>"")+('13 Jalons'!$D$9:$D$108<>"")+('13 Jalons'!$E$9:$E$108<>"")+('13 Jalons'!$F$9:$F$108<>"")+('13 Jalons'!$G$9:$G$108<>"")+('13 Jalons'!$H$9:$H$108<>"")+('13 Jalons'!$I$9:$I$108<>"")+('13 Jalons'!$J$9:$J$108<>""))>0)*('13 Jalons'!$I$9:$I$108<>"")) -> 0 | L33: =MAX(1,F33)*3 -> 3
B34: 14 | C34: Livrables | D34: Productions attendues | E34: Sous-phases, Chantiers, Personnes | F34: =SUMPRODUCT(((('14 Livrables'!$B$9:$B$158<>"")+('14 Livrables'!$C$9:$C$158<>"")+('14 Livrables'!$D$9:$D$158<>"")+('14 Livrables'!$E$9:$E$158<>"")+('14 Livrables'!$F$9:$F$158<>"")+('14 Livrables'!$G$9:$G$158<>""))>0)*1) -> 0 | G34: =K34&" / "&L34 -> 0 / 4 | H34: =REPT("━",ROUND(I34*12,0)) | I34: =K34/L34 -> 0 | J34: =IF(I34>=1,"Complet",IF(K34=0,"À démarrer","En cours")) -> À démarrer | K34: =SUMPRODUCT(((('14 Livrables'!$B$9:$B$158<>"")+('14 Livrables'!$C$9:$C$158<>"")+('14 Livrables'!$D$9:$D$158<>"")+('14 Livrables'!$E$9:$E$158<>"")+('14 Livrables'!$F$9:$F$158<>"")+('14 Livrables'!$G$9:$G$158<>""))>0)*('14 Livrables'!$B$9:$B$158<>""))+SUMPRODUCT(((('14 Livrables'!$B$9:$B$158<>"")+('14 Livrables'!$C$9:$C$158<>"")+('14 Livrables'!$D$9:$D$158<>"")+('14 Livrables'!$E$9:$E$158<>"")+('14 Livrables'!$F$9:$F$158<>"")+('14 Livrables'!$G$9:$G$158<>""))>0)*('14 Livrables'!$C$9:$C$158<>""))+SUMPRODUCT(((('14 Livrables'!$B$9:$B$158<>"")+('14 Livrables'!$C$9:$C$158<>"")+('14 Livrables'!$D$9:$D$158<>"")+('14 Livrables'!$E$9:$E$158<>"")+('14 Livrables'!$F$9:$F$158<>"")+('14 Livrables'!$G$9:$G$158<>""))>0)*('14 Livrables'!$E$9:$E$158<>""))+SUMPRODUCT(((('14 Livrables'!$B$9:$B$158<>"")+('14 Livrables'!$C$9:$C$158<>"")+('14 Livrables'!$D$9:$D$158<>"")+('14 Livrables'!$E$9:$E$158<>"")+('14 Livrables'!$F$9:$F$158<>"")+('14 Livrables'!$G$9:$G$158<>""))>0)*('14 Livrables'!$G$9:$G$158<>"")) -> 0 | L34: =MAX(1,F34)*4 -> 4
B36: Complétude d’un onglet = champs obligatoires remplis ÷ champs obligatoires attendus. Les champs facultatifs ne comptent pas.
B37: Une ligne est attendue dès qu’une de ses cellules est saisie : chacun de ses champs obligatoires est alors dû. Un onglet vide attend au moins une ligne.
B38: Complétude globale = total des champs obligatoires remplis ÷ total des champs obligatoires attendus, tous onglets confondus.

Sheet Glossaire
B2: Glossaire
B3: Les termes du référentiel, illustrés avec le projet RISE.
B6: Terme | C6: Définition | D6: Exemple | E6: Onglet
B7: Organisation
B8: Équipe | C8: Société ou entité qui travaille sur le projet. Chaque personne est rattachée à une équipe ; c’est elle qui indique pour quelle société la personne intervient. | D8: AMC Corp (client), Onepoint (AMOA), Codilog (intégrateur) | E8: 01 Équipes
B9: Rôle projet | C9: Responsabilité métier tenue sur le projet. Distinct de la permission. | D9: Responsable chantier, Sponsor exécutif | E9: 02 Rôles
B10: Permission | C10: Ce qu’une personne peut faire dans l’application. | D10: PMO : gère le référentiel · Lecteur : consulte | E10: 03 Personnes
B11: Affectation | C11: Lien daté entre une personne et un rôle. Plusieurs affectations simultanées sont possibles ; une fin vide signifie « en cours ». | D11: Karim Benali · Référent données · 01/09/2025 → en cours | E11: 04 Affectations
B12: Structure
B13: Référentiel | C13: Données de base du projet, saisies à l’initialisation et gérées par le PMO. Tout le reste de l’application s’appuie dessus. | D13: Lots, phases, chantiers, personnes, instances… | E13: Complétude
B14: Lot | C14: Vague de déploiement : un périmètre (sociétés, sites) et une période. | D14: Lot 1 · AMC Corp, Brand X et stores · 01/03/2024 → 30/06/2027 | E14: 07 Lots
B15: Phase | C15: Grande étape de la méthode projet, numérotée dans l’ordre. | D15: 5 · Deploy · 01/02/2026 → 30/06/2027 | E15: 08 Phases
B16: Sous-phase | C16: Découpage d’une phase. Son numéro commence par celui de la phase. | D16: 5.3 · Répétition générale (phase 5) | E16: 09 Sous-phases
B17: Chantier | C17: Domaine de travail qui traverse les phases, avec un responsable. | D17: C5 · Migration des données · Karim Benali | E17: 10 Chantiers
B18: Gouvernance
B19: Instance de pilotage | C19: Comité récurrent du projet, avec sa fréquence et ses membres. | D19: Comité de pilotage · mensuel · 6 membres | E19: 11 Instances
B20: Nom court | C20: Libellé abrégé de l’instance, utilisé dans le calendrier des comités et les infobulles. | D20: COPIL, COPROJ | E20: 11 Instances
B21: Membre | C21: Personne qui siège dans une instance. Les membres sont les participants par défaut des séances. | D21: Philippe Aubert · Président du COPIL | E21: 12 Membres
B22: Pilotage
B23: Jalon | C23: Date clé du projet, rattachée obligatoirement à une phase. Le code est attribué automatiquement. | D23: J08 · Go-Live Lot 1 · 01/04/2027 | E23: 13 Jalons
B24: Date prévue | C24: Date à laquelle le jalon est attendu aujourd’hui. | D24: 01/04/2027 | E24: 13 Jalons
B25: Date de référence | C25: Date figée lors de la validation du planning (baseline). L’écart se mesure par rapport à elle. Vide = date prévue. | D25: Référence v5 : 01/04/2027 | E25: 13 Jalons
B26: Livrable | C26: Production attendue, rattachée à une sous-phase, avec un responsable et une échéance. | D26: Plan de bascule détaillé · 5.3 | E26: 14 Livrables
B27: Conventions du fichier
B28: Clé | C28: Colonne calculée qui identifie une ligne. C’est la valeur proposée dans les listes des autres onglets. | D28: « 5 · Deploy » pour la phase 5 | E28: 08 Phases
B29: Liste ▾ | C29: Menu déroulant alimenté par un autre onglet ou par une liste fixe. Seules ses valeurs sont acceptées. | D29: La colonne Phase des jalons propose les clés de l’onglet Phases | E29: 13 Jalons
B30: Contrôle | C30: Colonne calculée qui vérifie la ligne : ✓ correct, ⚠ incohérence à corriger, ◔ avertissement. | D30: ⚠ Sous-phase hors phase | E30: 13 Jalons
B31: Complétude | C31: Champs obligatoires remplis ÷ champs obligatoires attendus. Une ligne est attendue dès qu’une de ses cellules est saisie ; un onglet vide attend au moins une ligne. | D31: Personnes : 10 lignes × 4 obligatoires = 40 attendus, 37 remplis → 93 % | E31: Complétude

Sheet Références
B2: Références
B3: Convention du choix multiple, rubriques de Info projet et valeurs acceptées par les colonnes à choix multiple.
B5: CHOIX MULTIPLE
B6: Plusieurs valeurs dans une cellule : séparez-les par un point-virgule « ; ». Exemple : 3 ; 4 ; 5. Les espaces autour du « ; » sont ignorés ; une valeur répétée ne compte qu’une fois.
B7: Colonnes concernées (10 Chantiers) : Phases (N° ou nom), Sous-phases (N°, ex. 3.1, dans une phase du chantier), Dépendances (noms ou codes des chantiers, ou Tous seul).
B9: RUBRIQUES DE INFO PROJET (onglet 06)
B10: Rubrique | C10: Forme | D10: Obligatoire | E10: Exemple
B11: Le client | C11: Libellé + valeur | D11: Non (raison sociale, secteur et pays viennent de 05 Projet) | E11: Effectifs · ~1 750 collaborateurs
B12: Marques du groupe | C12: Liste de valeurs | D12: Non | E12: Brand X
B13: Programme en une phrase | C13: Texte unique (une ligne) | D13: Oui | E13: Programme de transformation digitale du groupe…
B14: Enjeux stratégiques | C14: Liste de valeurs | D14: Oui, au moins une ligne | E14: Sortir de 19 ERP hétérogènes
B15: Périmètre fonctionnel | C15: Libellé + valeur | D15: Non | E15: Finance · Comptabilité, contrôle de gestion
B16: Périmètre applicatif | C16: Libellé + valeur | D16: Non | E16: Brand X · ERP principal
B17: Périmètre géographique | C17: Liste de valeurs | D17: Non | E17: France
B18: Périmètre juridique | C18: Liste de valeurs | D18: Non | E18: AMC Corp SAS
B21: VALEURS ACCEPTÉES (calculées à partir des onglets 07, 08 et 09)
B22: Phases (N° · Nom) | C22: Sous-phases (N° · Nom) | D22: Chantiers (code · nom)
B23: =IF('08 Phases'!$B$9="","",'08 Phases'!$B$9) | C23: =IF('09 Sous-phases'!$B$9="","",'09 Sous-phases'!$B$9) | D23: =IF('10 Chantiers'!$C$9="","",'10 Chantiers'!$B$9&" · "&'10 Chantiers'!$C$9)
B24: =IF('08 Phases'!$B$10="","",'08 Phases'!$B$10) | C24: =IF('09 Sous-phases'!$B$10="","",'09 Sous-phases'!$B$10) | D24: =IF('10 Chantiers'!$C$10="","",'10 Chantiers'!$B$10&" · "&'10 Chantiers'!$C$10)
B25: =IF('08 Phases'!$B$11="","",'08 Phases'!$B$11) | C25: =IF('09 Sous-phases'!$B$11="","",'09 Sous-phases'!$B$11) | D25: =IF('10 Chantiers'!$C$11="","",'10 Chantiers'!$B$11&" · "&'10 Chantiers'!$C$11)
B26: =IF('08 Phases'!$B$12="","",'08 Phases'!$B$12) | C26: =IF('09 Sous-phases'!$B$12="","",'09 Sous-phases'!$B$12) | D26: =IF('10 Chantiers'!$C$12="","",'10 Chantiers'!$B$12&" · "&'10 Chantiers'!$C$12)
B27: =IF('08 Phases'!$B$13="","",'08 Phases'!$B$13) | C27: =IF('09 Sous-phases'!$B$13="","",'09 Sous-phases'!$B$13) | D27: =IF('10 Chantiers'!$C$13="","",'10 Chantiers'!$B$13&" · "&'10 Chantiers'!$C$13)
B28: =IF('08 Phases'!$B$14="","",'08 Phases'!$B$14) | C28: =IF('09 Sous-phases'!$B$14="","",'09 Sous-phases'!$B$14) | D28: =IF('10 Chantiers'!$C$14="","",'10 Chantiers'!$B$14&" · "&'10 Chantiers'!$C$14)
B29: =IF('08 Phases'!$B$15="","",'08 Phases'!$B$15) | C29: =IF('09 Sous-phases'!$B$15="","",'09 Sous-phases'!$B$15) | D29: =IF('10 Chantiers'!$C$15="","",'10 Chantiers'!$B$15&" · "&'10 Chantiers'!$C$15)
B30: =IF('08 Phases'!$B$16="","",'08 Phases'!$B$16) | C30: =IF('09 Sous-phases'!$B$16="","",'09 Sous-phases'!$B$16) | D30: =IF('10 Chantiers'!$C$16="","",'10 Chantiers'!$B$16&" · "&'10 Chantiers'!$C$16)
B31: =IF('08 Phases'!$B$17="","",'08 Phases'!$B$17) | C31: =IF('09 Sous-phases'!$B$17="","",'09 Sous-phases'!$B$17) | D31: =IF('10 Chantiers'!$C$17="","",'10 Chantiers'!$B$17&" · "&'10 Chantiers'!$C$17)
B32: =IF('08 Phases'!$B$18="","",'08 Phases'!$B$18) | C32: =IF('09 Sous-phases'!$B$18="","",'09 Sous-phases'!$B$18) | D32: =IF('10 Chantiers'!$C$18="","",'10 Chantiers'!$B$18&" · "&'10 Chantiers'!$C$18)
B33: =IF('08 Phases'!$B$19="","",'08 Phases'!$B$19) | C33: =IF('09 Sous-phases'!$B$19="","",'09 Sous-phases'!$B$19) | D33: =IF('10 Chantiers'!$C$19="","",'10 Chantiers'!$B$19&" · "&'10 Chantiers'!$C$19)
B34: =IF('08 Phases'!$B$20="","",'08 Phases'!$B$20) | C34: =IF('09 Sous-phases'!$B$20="","",'09 Sous-phases'!$B$20) | D34: =IF('10 Chantiers'!$C$20="","",'10 Chantiers'!$B$20&" · "&'10 Chantiers'!$C$20)
B35: =IF('08 Phases'!$B$21="","",'08 Phases'!$B$21) | C35: =IF('09 Sous-phases'!$B$21="","",'09 Sous-phases'!$B$21) | D35: =IF('10 Chantiers'!$C$21="","",'10 Chantiers'!$B$21&" · "&'10 Chantiers'!$C$21)
B36: =IF('08 Phases'!$B$22="","",'08 Phases'!$B$22) | C36: =IF('09 Sous-phases'!$B$22="","",'09 Sous-phases'!$B$22) | D36: =IF('10 Chantiers'!$C$22="","",'10 Chantiers'!$B$22&" · "&'10 Chantiers'!$C$22)
B37: =IF('08 Phases'!$B$23="","",'08 Phases'!$B$23) | C37: =IF('09 Sous-phases'!$B$23="","",'09 Sous-phases'!$B$23) | D37: =IF('10 Chantiers'!$C$23="","",'10 Chantiers'!$B$23&" · "&'10 Chantiers'!$C$23)
B38: =IF('08 Phases'!$B$24="","",'08 Phases'!$B$24) | C38: =IF('09 Sous-phases'!$B$24="","",'09 Sous-phases'!$B$24) | D38: =IF('10 Chantiers'!$C$24="","",'10 Chantiers'!$B$24&" · "&'10 Chantiers'!$C$24)
B39: =IF('08 Phases'!$B$25="","",'08 Phases'!$B$25) | C39: =IF('09 Sous-phases'!$B$25="","",'09 Sous-phases'!$B$25) | D39: =IF('10 Chantiers'!$C$25="","",'10 Chantiers'!$B$25&" · "&'10 Chantiers'!$C$25)
B40: =IF('08 Phases'!$B$26="","",'08 Phases'!$B$26) | C40: =IF('09 Sous-phases'!$B$26="","",'09 Sous-phases'!$B$26) | D40: =IF('10 Chantiers'!$C$26="","",'10 Chantiers'!$B$26&" · "&'10 Chantiers'!$C$26)
B41: =IF('08 Phases'!$B$27="","",'08 Phases'!$B$27) | C41: =IF('09 Sous-phases'!$B$27="","",'09 Sous-phases'!$B$27) | D41: =IF('10 Chantiers'!$C$27="","",'10 Chantiers'!$B$27&" · "&'10 Chantiers'!$C$27)
B42: =IF('08 Phases'!$B$28="","",'08 Phases'!$B$28) | C42: =IF('09 Sous-phases'!$B$28="","",'09 Sous-phases'!$B$28) | D42: =IF('10 Chantiers'!$C$28="","",'10 Chantiers'!$B$28&" · "&'10 Chantiers'!$C$28)
B43: =IF('08 Phases'!$B$29="","",'08 Phases'!$B$29) | C43: =IF('09 Sous-phases'!$B$29="","",'09 Sous-phases'!$B$29) | D43: =IF('10 Chantiers'!$C$29="","",'10 Chantiers'!$B$29&" · "&'10 Chantiers'!$C$29)
B44: =IF('08 Phases'!$B$30="","",'08 Phases'!$B$30) | C44: =IF('09 Sous-phases'!$B$30="","",'09 Sous-phases'!$B$30) | D44: =IF('10 Chantiers'!$C$30="","",'10 Chantiers'!$B$30&" · "&'10 Chantiers'!$C$30)
B45: =IF('08 Phases'!$B$31="","",'08 Phases'!$B$31) | C45: =IF('09 Sous-phases'!$B$31="","",'09 Sous-phases'!$B$31) | D45: =IF('10 Chantiers'!$C$31="","",'10 Chantiers'!$B$31&" · "&'10 Chantiers'!$C$31)
...

Sheet 01 Équipes
B2: Équipes | E2: =Complétude!$I18 -> 0
B3: Sociétés ou entités qui travaillent sur le projet : client, cabinet AMOA, intégrateur, éditeur… | E3: ↩ Complétude
B4: ORGANISATION Étape 01 Dépend de : —
B5: Exemple : AMC Corp · Onepoint · Codilog
B7: OBLIGATOIRE | C7: FACULTATIF | D7: CALCULÉ | E7: CONTRÔLE
B8: Nom | C8: Description | D8: Personnes | E8: Contrôle
D9: =IF(B9="","",COUNTIF('03 Personnes'!$D$9:$D$158,B9)) | E9: =IF(B9="","",IF(COUNTIF($B$9:$B$38,B9)>1,"⚠ Nom en double","✓"))
D10: =IF(B10="","",COUNTIF('03 Personnes'!$D$9:$D$158,B10)) | E10: =IF(B10="","",IF(COUNTIF($B$9:$B$38,B10)>1,"⚠ Nom en double","✓"))
D11: =IF(B11="","",COUNTIF('03 Personnes'!$D$9:$D$158,B11)) | E11: =IF(B11="","",IF(COUNTIF($B$9:$B$38,B11)>1,"⚠ Nom en double","✓"))
D12: =IF(B12="","",COUNTIF('03 Personnes'!$D$9:$D$158,B12)) | E12: =IF(B12="","",IF(COUNTIF($B$9:$B$38,B12)>1,"⚠ Nom en double","✓"))
D13: =IF(B13="","",COUNTIF('03 Personnes'!$D$9:$D$158,B13)) | E13: =IF(B13="","",IF(COUNTIF($B$9:$B$38,B13)>1,"⚠ Nom en double","✓"))
D14: =IF(B14="","",COUNTIF('03 Personnes'!$D$9:$D$158,B14)) | E14: =IF(B14="","",IF(COUNTIF($B$9:$B$38,B14)>1,"⚠ Nom en double","✓"))
D15: =IF(B15="","",COUNTIF('03 Personnes'!$D$9:$D$158,B15)) | E15: =IF(B15="","",IF(COUNTIF($B$9:$B$38,B15)>1,"⚠ Nom en double","✓"))
D16: =IF(B16="","",COUNTIF('03 Personnes'!$D$9:$D$158,B16)) | E16: =IF(B16="","",IF(COUNTIF($B$9:$B$38,B16)>1,"⚠ Nom en double","✓"))
D17: =IF(B17="","",COUNTIF('03 Personnes'!$D$9:$D$158,B17)) | E17: =IF(B17="","",IF(COUNTIF($B$9:$B$38,B17)>1,"⚠ Nom en double","✓"))
D18: =IF(B18="","",COUNTIF('03 Personnes'!$D$9:$D$158,B18)) | E18: =IF(B18="","",IF(COUNTIF($B$9:$B$38,B18)>1,"⚠ Nom en double","✓"))
D19: =IF(B19="","",COUNTIF('03 Personnes'!$D$9:$D$158,B19)) | E19: =IF(B19="","",IF(COUNTIF($B$9:$B$38,B19)>1,"⚠ Nom en double","✓"))
D20: =IF(B20="","",COUNTIF('03 Personnes'!$D$9:$D$158,B20)) | E20: =IF(B20="","",IF(COUNTIF($B$9:$B$38,B20)>1,"⚠ Nom en double","✓"))
... D38: =IF(B38="","",COUNTIF('03 Personnes'!$D$9:$D$158,B38)) | E38: =IF(B38="","",IF(COUNTIF($B$9:$B$38,B38)>1,"⚠ Nom en double","✓"))

Sheet 02 Rôles
B2: Rôles projet | D2: =Complétude!$I19 -> 0
B3: Rôles métier tenus sur le projet. Un rôle n’est pas une permission dans l’application. | D3: ↩ Complétude
B4: ORGANISATION Étape 02 Dépend de : —
B5: Exemple : Responsable chantier · pilote un chantier, son planning et ses anomalies
B7: OBLIGATOIRE | C7: FACULTATIF | D7: CALCULÉ
B8: Libellé | C8: Description | D8: Affectations actives
D9: =IF(B9="","",COUNTIFS('04 Affectations'!$C$9:$C$208,B9,'04 Affectations'!$G$9:$G$208,"Oui"))
D10: =IF(B10="","",COUNTIFS('04 Affectations'!$C$9:$C$208,B10,'04 Affectations'!$G$9:$G$208,"Oui"))
D11: =IF(B11="","",COUNTIFS('04 Affectations'!$C$9:$C$208,B11,'04 Affectations'!$G$9:$G$208,"Oui"))
D12: =IF(B12="","",COUNTIFS('04 Affectations'!$C$9:$C$208,B12,'04 Affectations'!$G$9:$G$208,"Oui"))
D13: =IF(B13="","",COUNTIFS('04 Affectations'!$C$9:$C$208,B13,'04 Affectations'!$G$9:$G$208,"Oui"))
D14: =IF(B14="","",COUNTIFS('04 Affectations'!$C$9:$C$208,B14,'04 Affectations'!$G$9:$G$208,"Oui"))
D15: =IF(B15="","",COUNTIFS('04 Affectations'!$C$9:$C$208,B15,'04 Affectations'!$G$9:$G$208,"Oui"))
D16: =IF(B16="","",COUNTIFS('04 Affectations'!$C$9:$C$208,B16,'04 Affectations'!$G$9:$G$208,"Oui"))
D17: =IF(B17="","",COUNTIFS('04 Affectations'!$C$9:$C$208,B17,'04 Affectations'!$G$9:$G$208,"Oui"))
D18: =IF(B18="","",COUNTIFS('04 Affectations'!$C$9:$C$208,B18,'04 Affectations'!$G$9:$G$208,"Oui"))
D19: =IF(B19="","",COUNTIFS('04 Affectations'!$C$9:$C$208,B19,'04 Affectations'!$G$9:$G$208,"Oui"))
D20: =IF(B20="","",COUNTIFS('04 Affectations'!$C$9:$C$208,B20,'04 Affectations'!$G$9:$G$208,"Oui"))
... D48: =IF(B48="","",COUNTIFS('04 Affectations'!$C$9:$C$208,B48,'04 Affectations'!$G$9:$G$208,"Oui"))

Sheet 03 Personnes
B2: Personnes | H2: =Complétude!$I20 -> 0
B3: Toutes les personnes du projet, rattachées à leur équipe. Le nom complet sert de référence dans les autres onglets. | H3: ↩ Complétude
B4: ORGANISATION Étape 03 Dépend de : Équipes
B5: Exemple : Karim Benali · karim.benali@amc.com · AMC Corp · Responsable IT ERP · Contributeur
B7: OBLIGATOIRE | C7: OBLIGATOIRE | D7: OBLIGATOIRE ▾ | E7: FACULTATIF | F7: OBLIGATOIRE ▾ | G7: FACULTATIF ▾ | H7: CONTRÔLE
B8: Nom complet | C8: Email | D8: Équipe | E8: Fonction | F8: Permission | G8: Actif | H8: Contrôle
H9: =IF(B9="","",IF(COUNTIF($B$9:$B$158,B9)>1,"⚠ Nom en double",IF(AND(C9<>"",ISERROR(FIND("@",C9))),"⚠ Email invalide",IF(AND(C9<>"",COUNTIF($C$9:$C$158,C9)>1),"⚠ Email en double","✓"))))
H10: =IF(B10="","",IF(COUNTIF($B$9:$B$158,B10)>1,"⚠ Nom en double",IF(AND(C10<>"",ISERROR(FIND("@",C10))),"⚠ Email invalide",IF(AND(C10<>"",COUNTIF($C$9:$C$158,C10)>1),"⚠ Email en double","✓"))))
H11: =IF(B11="","",IF(COUNTIF($B$9:$B$158,B11)>1,"⚠ Nom en double",IF(AND(C11<>"",ISERROR(FIND("@",C11))),"⚠ Email invalide",IF(AND(C11<>"",COUNTIF($C$9:$C$158,C11)>1),"⚠ Email en double","✓"))))
H12: =IF(B12="","",IF(COUNTIF($B$9:$B$158,B12)>1,"⚠ Nom en double",IF(AND(C12<>"",ISERROR(FIND("@",C12))),"⚠ Email invalide",IF(AND(C12<>"",COUNTIF($C$9:$C$158,C12)>1),"⚠ Email en double","✓"))))
H13: =IF(B13="","",IF(COUNTIF($B$9:$B$158,B13)>1,"⚠ Nom en double",IF(AND(C13<>"",ISERROR(FIND("@",C13))),"⚠ Email invalide",IF(AND(C13<>"",COUNTIF($C$9:$C$158,C13)>1),"⚠ Email en double","✓"))))
H14: =IF(B14="","",IF(COUNTIF($B$9:$B$158,B14)>1,"⚠ Nom en double",IF(AND(C14<>"",ISERROR(FIND("@",C14))),"⚠ Email invalide",IF(AND(C14<>"",COUNTIF($C$9:$C$158,C14)>1),"⚠ Email en double","✓"))))
H15: =IF(B15="","",IF(COUNTIF($B$9:$B$158,B15)>1,"⚠ Nom en double",IF(AND(C15<>"",ISERROR(FIND("@",C15))),"⚠ Email invalide",IF(AND(C15<>"",COUNTIF($C$9:$C$158,C15)>1),"⚠ Email en double","✓"))))
H16: =IF(B16="","",IF(COUNTIF($B$9:$B$158,B16)>1,"⚠ Nom en double",IF(AND(C16<>"",ISERROR(FIND("@",C16))),"⚠ Email invalide",IF(AND(C16<>"",COUNTIF($C$9:$C$158,C16)>1),"⚠ Email en double","✓"))))
H17: =IF(B17="","",IF(COUNTIF($B$9:$B$158,B17)>1,"⚠ Nom en double",IF(AND(C17<>"",ISERROR(FIND("@",C17))),"⚠ Email invalide",IF(AND(C17<>"",COUNTIF($C$9:$C$158,C17)>1),"⚠ Email en double","✓"))))
H18: =IF(B18="","",IF(COUNTIF($B$9:$B$158,B18)>1,"⚠ Nom en double",IF(AND(C18<>"",ISERROR(FIND("@",C18))),"⚠ Email invalide",IF(AND(C18<>"",COUNTIF($C$9:$C$158,C18)>1),"⚠ Email en double","✓"))))
H19: =IF(B19="","",IF(COUNTIF($B$9:$B$158,B19)>1,"⚠ Nom en double",IF(AND(C19<>"",ISERROR(FIND("@",C19))),"⚠ Email invalide",IF(AND(C19<>"",COUNTIF($C$9:$C$158,C19)>1),"⚠ Email en double","✓"))))
H20: =IF(B20="","",IF(COUNTIF($B$9:$B$158,B20)>1,"⚠ Nom en double",IF(AND(C20<>"",ISERROR(FIND("@",C20))),"⚠ Email invalide",IF(AND(C20<>"",COUNTIF($C$9:$C$158,C20)>1),"⚠ Email en double","✓"))))
... H158: =IF(B158="","",IF(COUNTIF($B$9:$B$158,B158)>1,"⚠ Nom en double",IF(AND(C158<>"",ISERROR(FIND("@",C158))),"⚠ Email invalide",IF(AND(C158<>"",COUNTIF($C$9:$C$158,C158)>1),"⚠ Email en double","✓"))))

Sheet 04 Affectations
B2: Affectations | H2: =Complétude!$I21 -> 0
B3: Qui tient quel rôle, et depuis quand. Plusieurs rôles simultanés possibles ; l’historique est conservé. | H3: ↩ Complétude
B4: ORGANISATION Étape 04 Dépend de : Personnes, Rôles
B5: Exemple : Karim Benali · Responsable migration · 01/09/2025 → fin vide = en cours
B7: OBLIGATOIRE ▾ | C7: OBLIGATOIRE ▾ | D7: CALCULÉ | E7: OBLIGATOIRE | F7: FACULTATIF | G7: CALCULÉ | H7: CONTRÔLE
B8: Personne | C8: Rôle | D8: Équipe | E8: Début | F8: Fin | G8: Active | H8: Contrôle
D9: =IF(B9="","",IFERROR(INDEX('03 Personnes'!$D$9:$D$158,MATCH(B9,'03 Personnes'!$B$9:$B$158,0)),"—")) | G9: =IF(B9="","",IF(OR(F9="",F9>=TODAY()),"Oui","Non")) | H9: =IF(B9="","",IF(AND(E9<>"",F9<>"",F9<E9),"⚠ Fin avant début",IF(COUNTIFS($B$9:$B$208,B9,$C$9:$C$208,C9,$E$9:$E$208,E9)>1,"⚠ Doublon","✓")))
D10: =IF(B10="","",IFERROR(INDEX('03 Personnes'!$D$9:$D$158,MATCH(B10,'03 Personnes'!$B$9:$B$158,0)),"—")) | G10: =IF(B10="","",IF(OR(F10="",F10>=TODAY()),"Oui","Non")) | H10: =IF(B10="","",IF(AND(E10<>"",F10<>"",F10<E10),"⚠ Fin avant début",IF(COUNTIFS($B$9:$B$208,B10,$C$9:$C$208,C10,$E$9:$E$208,E10)>1,"⚠ Doublon","✓")))
D11: =IF(B11="","",IFERROR(INDEX('03 Personnes'!$D$9:$D$158,MATCH(B11,'03 Personnes'!$B$9:$B$158,0)),"—")) | G11: =IF(B11="","",IF(OR(F11="",F11>=TODAY()),"Oui","Non")) | H11: =IF(B11="","",IF(AND(E11<>"",F11<>"",F11<E11),"⚠ Fin avant début",IF(COUNTIFS($B$9:$B$208,B11,$C$9:$C$208,C11,$E$9:$E$208,E11)>1,"⚠ Doublon","✓")))
D12: =IF(B12="","",IFERROR(INDEX('03 Personnes'!$D$9:$D$158,MATCH(B12,'03 Personnes'!$B$9:$B$158,0)),"—")) | G12: =IF(B12="","",IF(OR(F12="",F12>=TODAY()),"Oui","Non")) | H12: =IF(B12="","",IF(AND(E12<>"",F12<>"",F12<E12),"⚠ Fin avant début",IF(COUNTIFS($B$9:$B$208,B12,$C$9:$C$208,C12,$E$9:$E$208,E12)>1,"⚠ Doublon","✓")))
D13: =IF(B13="","",IFERROR(INDEX('03 Personnes'!$D$9:$D$158,MATCH(B13,'03 Personnes'!$B$9:$B$158,0)),"—")) | G13: =IF(B13="","",IF(OR(F13="",F13>=TODAY()),"Oui","Non")) | H13: =IF(B13="","",IF(AND(E13<>"",F13<>"",F13<E13),"⚠ Fin avant début",IF(COUNTIFS($B$9:$B$208,B13,$C$9:$C$208,C13,$E$9:$E$208,E13)>1,"⚠ Doublon","✓")))
D14: =IF(B14="","",IFERROR(INDEX('03 Personnes'!$D$9:$D$158,MATCH(B14,'03 Personnes'!$B$9:$B$158,0)),"—")) | G14: =IF(B14="","",IF(OR(F14="",F14>=TODAY()),"Oui","Non")) | H14: =IF(B14="","",IF(AND(E14<>"",F14<>"",F14<E14),"⚠ Fin avant début",IF(COUNTIFS($B$9:$B$208,B14,$C$9:$C$208,C14,$E$9:$E$208,E14)>1,"⚠ Doublon","✓")))
D15: =IF(B15="","",IFERROR(INDEX('03 Personnes'!$D$9:$D$158,MATCH(B15,'03 Personnes'!$B$9:$B$158,0)),"—")) | G15: =IF(B15="","",IF(OR(F15="",F15>=TODAY()),"Oui","Non")) | H15: =IF(B15="","",IF(AND(E15<>"",F15<>"",F15<E15),"⚠ Fin avant début",IF(COUNTIFS($B$9:$B$208,B15,$C$9:$C$208,C15,$E$9:$E$208,E15)>1,"⚠ Doublon","✓")))
D16: =IF(B16="","",IFERROR(INDEX('03 Personnes'!$D$9:$D$158,MATCH(B16,'03 Personnes'!$B$9:$B$158,0)),"—")) | G16: =IF(B16="","",IF(OR(F16="",F16>=TODAY()),"Oui","Non")) | H16: =IF(B16="","",IF(AND(E16<>"",F16<>"",F16<E16),"⚠ Fin avant début",IF(COUNTIFS($B$9:$B$208,B16,$C$9:$C$208,C16,$E$9:$E$208,E16)>1,"⚠ Doublon","✓")))
D17: =IF(B17="","",IFERROR(INDEX('03 Personnes'!$D$9:$D$158,MATCH(B17,'03 Personnes'!$B$9:$B$158,0)),"—")) | G17: =IF(B17="","",IF(OR(F17="",F17>=TODAY()),"Oui","Non")) | H17: =IF(B17="","",IF(AND(E17<>"",F17<>"",F17<E17),"⚠ Fin avant début",IF(COUNTIFS($B$9:$B$208,B17,$C$9:$C$208,C17,$E$9:$E$208,E17)>1,"⚠ Doublon","✓")))
D18: =IF(B18="","",IFERROR(INDEX('03 Personnes'!$D$9:$D$158,MATCH(B18,'03 Personnes'!$B$9:$B$158,0)),"—")) | G18: =IF(B18="","",IF(OR(F18="",F18>=TODAY()),"Oui","Non")) | H18: =IF(B18="","",IF(AND(E18<>"",F18<>"",F18<E18),"⚠ Fin avant début",IF(COUNTIFS($B$9:$B$208,B18,$C$9:$C$208,C18,$E$9:$E$208,E18)>1,"⚠ Doublon","✓")))
D19: =IF(B19="","",IFERROR(INDEX('03 Personnes'!$D$9:$D$158,MATCH(B19,'03 Personnes'!$B$9:$B$158,0)),"—")) | G19: =IF(B19="","",IF(OR(F19="",F19>=TODAY()),"Oui","Non")) | H19: =IF(B19="","",IF(AND(E19<>"",F19<>"",F19<E19),"⚠ Fin avant début",IF(COUNTIFS($B$9:$B$208,B19,$C$9:$C$208,C19,$E$9:$E$208,E19)>1,"⚠ Doublon","✓")))
D20: =IF(B20="","",IFERROR(INDEX('03 Personnes'!$D$9:$D$158,MATCH(B20,'03 Personnes'!$B$9:$B$158,0)),"—")) | G20: =IF(B20="","",IF(OR(F20="",F20>=TODAY()),"Oui","Non")) | H20: =IF(B20="","",IF(AND(E20<>"",F20<>"",F20<E20),"⚠ Fin avant début",IF(COUNTIFS($B$9:$B$208,B20,$C$9:$C$208,C20,$E$9:$E$208,E20)>1,"⚠ Doublon","✓")))
... D208: =IF(B208="","",IFERROR(INDEX('03 Personnes'!$D$9:$D$158,MATCH(B208,'03 Personnes'!$B$9:$B$158,0)),"—")) | G208: =IF(B208="","",IF(OR(F208="",F208>=TODAY()),"Oui","Non")) | H208: =IF(B208="","",IF(AND(E208<>"",F208<>"",F208<E208),"⚠ Fin avant début",IF(COUNTIFS($B$9:$B$208,B208,$C$9:$C$208,C208,$E$9:$E$208,E208)>1,"⚠ Doublon","✓")))

Sheet 05 Projet
B2: Projet | E2: =Complétude!$I25 -> 0
B3: Identité du client et du projet. Une seule valeur par champ. | E3: ↩ Complétude
B4: STRUCTURE Étape 05 Dépend de : Équipes, Personnes
B5: Exemple : AMC Corp · RISE · Implémentation Brand X + CRM · Europe/Paris
B7: Client
B8: Nom du client | C8: OBLIGATOIRE
B9: Secteur d’activité | C9: FACULTATIF
B10: Pays | C10: OBLIGATOIRE
B11: Ville du projet | C11: FACULTATIF | E11: Une seule commune, ex. Palaiseau
B12: Code postal | C12: FACULTATIF | E12: Ex. 91120 : précise la météo et le trafic
B13: Projet
B14: Code projet | C14: OBLIGATOIRE | E14: Court et unique, ex. RISE
B15: Nom du projet | C15: OBLIGATOIRE
B16: Objectifs | C16: FACULTATIF | E16: Deux ou trois phrases
B17: Éditeur de la solution | C17: FACULTATIF ▾ | E17: Choisi parmi les équipes
B18: Intégrateur | C18: FACULTATIF ▾ | E18: Choisi parmi les équipes
B19: Date de démarrage | C19: OBLIGATOIRE
B20: Date de fin cible | C20: OBLIGATOIRE
B21: Fuseau horaire | C21: OBLIGATOIRE ▾
B22: Statut | C22: FACULTATIF ▾
B23: Directeur de programme | C23: OBLIGATOIRE ▾
B24: Sponsor | C24: FACULTATIF ▾
D26: =IF(OR(D19="",D20=""),"",IF(D20<D19,"⚠ Fin cible avant démarrage","✓ Dates cohérentes"))

Sheet 06 Info projet
B2: Info projet | E2: =Complétude!$I24 -> 0
B3: Contexte du client et périmètre du projet (onglet Fiche projet du Cockpit). Une ligne par élément ; les rubriques sont listées dans l’onglet Références. | E3: ↩ Complétude
B4: STRUCTURE Étape 06 Dépend de : Projet
B5: Exemple : Enjeux stratégiques · (vide) · Sortir de 19 ERP hétérogènes — Périmètre fonctionnel · Finance · Comptabilité, contrôle de gestion
B7: OBLIGATOIRE ▾ | C7: FACULTATIF (obligatoire pour les rubriques Libellé + valeur) | D7: OBLIGATOIRE | E7: CONTRÔLE
B8: Rubrique | C8: Libellé | D8: Valeur | E8: Contrôle
E9: =IF(AND(B9="",C9="",D9=""),"",IF(B9="","⚠ Rubrique manquante",IF(ISNA(MATCH(B9,L_Rubriques,0)),"⚠ Rubrique inconnue",IF(D9="","⚠ Valeur manquante",IF(AND(COUNTIF(L_RubriquesPaires,B9)>0,C9=""),"⚠ Libellé manquant",IF(AND(B9="Programme en une phrase",COUNTIF($B$9:B9,B9)>1),"⚠ Une seule ligne",IF(AND(COUNTIF(L_RubriquesPaires,B9)=0,C9<>""),"◔ Libellé ignoré","✓")))))))
E10: =IF(AND(B10="",C10="",D10=""),"",IF(B10="","⚠ Rubrique manquante",IF(ISNA(MATCH(B10,L_Rubriques,0)),"⚠ Rubrique inconnue",IF(D10="","⚠ Valeur manquante",IF(AND(COUNTIF(L_RubriquesPaires,B10)>0,C10=""),"⚠ Libellé manquant",IF(AND(B10="Programme en une phrase",COUNTIF($B$9:B10,B10)>1),"⚠ Une seule ligne",IF(AND(COUNTIF(L_RubriquesPaires,B10)=0,C10<>""),"◔ Libellé ignoré","✓")))))))
E11: =IF(AND(B11="",C11="",D11=""),"",IF(B11="","⚠ Rubrique manquante",IF(ISNA(MATCH(B11,L_Rubriques,0)),"⚠ Rubrique inconnue",IF(D11="","⚠ Valeur manquante",IF(AND(COUNTIF(L_RubriquesPaires,B11)>0,C11=""),"⚠ Libellé manquant",IF(AND(B11="Programme en une phrase",COUNTIF($B$9:B11,B11)>1),"⚠ Une seule ligne",IF(AND(COUNTIF(L_RubriquesPaires,B11)=0,C11<>""),"◔ Libellé ignoré","✓")))))))
E12: =IF(AND(B12="",C12="",D12=""),"",IF(B12="","⚠ Rubrique manquante",IF(ISNA(MATCH(B12,L_Rubriques,0)),"⚠ Rubrique inconnue",IF(D12="","⚠ Valeur manquante",IF(AND(COUNTIF(L_RubriquesPaires,B12)>0,C12=""),"⚠ Libellé manquant",IF(AND(B12="Programme en une phrase",COUNTIF($B$9:B12,B12)>1),"⚠ Une seule ligne",IF(AND(COUNTIF(L_RubriquesPaires,B12)=0,C12<>""),"◔ Libellé ignoré","✓")))))))
E13: =IF(AND(B13="",C13="",D13=""),"",IF(B13="","⚠ Rubrique manquante",IF(ISNA(MATCH(B13,L_Rubriques,0)),"⚠ Rubrique inconnue",IF(D13="","⚠ Valeur manquante",IF(AND(COUNTIF(L_RubriquesPaires,B13)>0,C13=""),"⚠ Libellé manquant",IF(AND(B13="Programme en une phrase",COUNTIF($B$9:B13,B13)>1),"⚠ Une seule ligne",IF(AND(COUNTIF(L_RubriquesPaires,B13)=0,C13<>""),"◔ Libellé ignoré","✓")))))))
E14: =IF(AND(B14="",C14="",D14=""),"",IF(B14="","⚠ Rubrique manquante",IF(ISNA(MATCH(B14,L_Rubriques,0)),"⚠ Rubrique inconnue",IF(D14="","⚠ Valeur manquante",IF(AND(COUNTIF(L_RubriquesPaires,B14)>0,C14=""),"⚠ Libellé manquant",IF(AND(B14="Programme en une phrase",COUNTIF($B$9:B14,B14)>1),"⚠ Une seule ligne",IF(AND(COUNTIF(L_RubriquesPaires,B14)=0,C14<>""),"◔ Libellé ignoré","✓")))))))
E15: =IF(AND(B15="",C15="",D15=""),"",IF(B15="","⚠ Rubrique manquante",IF(ISNA(MATCH(B15,L_Rubriques,0)),"⚠ Rubrique inconnue",IF(D15="","⚠ Valeur manquante",IF(AND(COUNTIF(L_RubriquesPaires,B15)>0,C15=""),"⚠ Libellé manquant",IF(AND(B15="Programme en une phrase",COUNTIF($B$9:B15,B15)>1),"⚠ Une seule ligne",IF(AND(COUNTIF(L_RubriquesPaires,B15)=0,C15<>""),"◔ Libellé ignoré","✓")))))))
E16: =IF(AND(B16="",C16="",D16=""),"",IF(B16="","⚠ Rubrique manquante",IF(ISNA(MATCH(B16,L_Rubriques,0)),"⚠ Rubrique inconnue",IF(D16="","⚠ Valeur manquante",IF(AND(COUNTIF(L_RubriquesPaires,B16)>0,C16=""),"⚠ Libellé manquant",IF(AND(B16="Programme en une phrase",COUNTIF($B$9:B16,B16)>1),"⚠ Une seule ligne",IF(AND(COUNTIF(L_RubriquesPaires,B16)=0,C16<>""),"◔ Libellé ignoré","✓")))))))
E17: =IF(AND(B17="",C17="",D17=""),"",IF(B17="","⚠ Rubrique manquante",IF(ISNA(MATCH(B17,L_Rubriques,0)),"⚠ Rubrique inconnue",IF(D17="","⚠ Valeur manquante",IF(AND(COUNTIF(L_RubriquesPaires,B17)>0,C17=""),"⚠ Libellé manquant",IF(AND(B17="Programme en une phrase",COUNTIF($B$9:B17,B17)>1),"⚠ Une seule ligne",IF(AND(COUNTIF(L_RubriquesPaires,B17)=0,C17<>""),"◔ Libellé ignoré","✓")))))))
E18: =IF(AND(B18="",C18="",D18=""),"",IF(B18="","⚠ Rubrique manquante",IF(ISNA(MATCH(B18,L_Rubriques,0)),"⚠ Rubrique inconnue",IF(D18="","⚠ Valeur manquante",IF(AND(COUNTIF(L_RubriquesPaires,B18)>0,C18=""),"⚠ Libellé manquant",IF(AND(B18="Programme en une phrase",COUNTIF($B$9:B18,B18)>1),"⚠ Une seule ligne",IF(AND(COUNTIF(L_RubriquesPaires,B18)=0,C18<>""),"◔ Libellé ignoré","✓")))))))
E19: =IF(AND(B19="",C19="",D19=""),"",IF(B19="","⚠ Rubrique manquante",IF(ISNA(MATCH(B19,L_Rubriques,0)),"⚠ Rubrique inconnue",IF(D19="","⚠ Valeur manquante",IF(AND(COUNTIF(L_RubriquesPaires,B19)>0,C19=""),"⚠ Libellé manquant",IF(AND(B19="Programme en une phrase",COUNTIF($B$9:B19,B19)>1),"⚠ Une seule ligne",IF(AND(COUNTIF(L_RubriquesPaires,B19)=0,C19<>""),"◔ Libellé ignoré","✓")))))))
E20: =IF(AND(B20="",C20="",D20=""),"",IF(B20="","⚠ Rubrique manquante",IF(ISNA(MATCH(B20,L_Rubriques,0)),"⚠ Rubrique inconnue",IF(D20="","⚠ Valeur manquante",IF(AND(COUNTIF(L_RubriquesPaires,B20)>0,C20=""),"⚠ Libellé manquant",IF(AND(B20="Programme en une phrase",COUNTIF($B$9:B20,B20)>1),"⚠ Une seule ligne",IF(AND(COUNTIF(L_RubriquesPaires,B20)=0,C20<>""),"◔ Libellé ignoré","✓")))))))
... E128: =IF(AND(B128="",C128="",D128=""),"",IF(B128="","⚠ Rubrique manquante",IF(ISNA(MATCH(B128,L_Rubriques,0)),"⚠ Rubrique inconnue",IF(D128="","⚠ Valeur manquante",IF(AND(COUNTIF(L_RubriquesPaires,B128)>0,C128=""),"⚠ Libellé manquant",IF(AND(B128="Programme en une phrase",COUNTIF($B$9:B128,B128)>1),"⚠ Une seule ligne",IF(AND(COUNTIF(L_RubriquesPaires,B128)=0,C128<>""),"◔ Libellé ignoré","✓")))))))

Sheet 07 Lots
B2: Lots | I2: =Complétude!$I25 -> 0
B3: Vagues de déploiement du projet. Chaque lot a un périmètre et une période. | I3: ↩ Complétude
B4: STRUCTURE Étape 07 Dépend de : Personnes
B5: Exemple : Lot 1 · AMC Corp, Brand X et stores · 01/03/2024 → 30/06/2027
B7: CALCULÉ | C7: OBLIGATOIRE | D7: OBLIGATOIRE | E7: OBLIGATOIRE | F7: OBLIGATOIRE | G7: FACULTATIF ▾ | H7: FACULTATIF ▾ | I7: CONTRÔLE
B8: Clé | C8: N° | D8: Périmètre | E8: Début | F8: Fin | G8: Statut | H8: Responsable | I8: Contrôle
B9: =IF(C9="","","Lot "&C9) | I9: =IF(C9="","",IF(COUNTIF($C$9:$C$38,C9)>1,"⚠ N° en double",IF(AND(E9<>"",F9<>"",F9<E9),"⚠ Fin avant début","✓")))
B10: =IF(C10="","","Lot "&C10) | I10: =IF(C10="","",IF(COUNTIF($C$9:$C$38,C10)>1,"⚠ N° en double",IF(AND(E10<>"",F10<>"",F10<E10),"⚠ Fin avant début","✓")))
B11: =IF(C11="","","Lot "&C11) | I11: =IF(C11="","",IF(COUNTIF($C$9:$C$38,C11)>1,"⚠ N° en double",IF(AND(E11<>"",F11<>"",F11<E11),"⚠ Fin avant début","✓")))
B12: =IF(C12="","","Lot "&C12) | I12: =IF(C12="","",IF(COUNTIF($C$9:$C$38,C12)>1,"⚠ N° en double",IF(AND(E12<>"",F12<>"",F12<E12),"⚠ Fin avant début","✓")))
B13: =IF(C13="","","Lot "&C13) | I13: =IF(C13="","",IF(COUNTIF($C$9:$C$38,C13)>1,"⚠ N° en double",IF(AND(E13<>"",F13<>"",F13<E13),"⚠ Fin avant début","✓")))
B14: =IF(C14="","","Lot "&C14) | I14: =IF(C14="","",IF(COUNTIF($C$9:$C$38,C14)>1,"⚠ N° en double",IF(AND(E14<>"",F14<>"",F14<E14),"⚠ Fin avant début","✓")))
B15: =IF(C15="","","Lot "&C15) | I15: =IF(C15="","",IF(COUNTIF($C$9:$C$38,C15)>1,"⚠ N° en double",IF(AND(E15<>"",F15<>"",F15<E15),"⚠ Fin avant début","✓")))
B16: =IF(C16="","","Lot "&C16) | I16: =IF(C16="","",IF(COUNTIF($C$9:$C$38,C16)>1,"⚠ N° en double",IF(AND(E16<>"",F16<>"",F16<E16),"⚠ Fin avant début","✓")))
B17: =IF(C17="","","Lot "&C17) | I17: =IF(C17="","",IF(COUNTIF($C$9:$C$38,C17)>1,"⚠ N° en double",IF(AND(E17<>"",F17<>"",F17<E17),"⚠ Fin avant début","✓")))
B18: =IF(C18="","","Lot "&C18) | I18: =IF(C18="","",IF(COUNTIF($C$9:$C$38,C18)>1,"⚠ N° en double",IF(AND(E18<>"",F18<>"",F18<E18),"⚠ Fin avant début","✓")))
B19: =IF(C19="","","Lot "&C19) | I19: =IF(C19="","",IF(COUNTIF($C$9:$C$38,C19)>1,"⚠ N° en double",IF(AND(E19<>"",F19<>"",F19<E19),"⚠ Fin avant début","✓")))
B20: =IF(C20="","","Lot "&C20) | I20: =IF(C20="","",IF(COUNTIF($C$9:$C$38,C20)>1,"⚠ N° en double",IF(AND(E20<>"",F20<>"",F20<E20),"⚠ Fin avant début","✓")))
... B38: =IF(C38="","","Lot "&C38) | I38: =IF(C38="","",IF(COUNTIF($C$9:$C$38,C38)>1,"⚠ N° en double",IF(AND(E38<>"",F38<>"",F38<E38),"⚠ Fin avant début","✓")))

Sheet 08 Phases
B2: Phases | J2: =Complétude!$I26 -> 0
B3: Grandes étapes de la méthode (Discover, Prepare, Explore…), numérotées dans l’ordre. | J3: ↩ Complétude
B4: STRUCTURE Étape 08 Dépend de : Lots
B5: Exemple : 5 · Deploy · Lot 1 · 01/02/2026 → 30/06/2027 · En cours
B7: CALCULÉ | C7: OBLIGATOIRE | D7: OBLIGATOIRE | E7: OBLIGATOIRE ▾ | F7: OBLIGATOIRE | G7: OBLIGATOIRE | H7: FACULTATIF ▾ | I7: FACULTATIF | J7: CONTRÔLE
B8: Clé | C8: N° | D8: Nom | E8: Lot | F8: Début | G8: Fin | H8: Statut | I8: Description | J8: Contrôle
B9: =IF(C9="","",C9&" · "&D9) | J9: =IF(C9="","",IF(COUNTIF($C$9:$C$38,C9)>1,"⚠ N° en double",IF(AND(F9<>"",G9<>"",G9<F9),"⚠ Fin avant début","✓")))
B10: =IF(C10="","",C10&" · "&D10) | J10: =IF(C10="","",IF(COUNTIF($C$9:$C$38,C10)>1,"⚠ N° en double",IF(AND(F10<>"",G10<>"",G10<F10),"⚠ Fin avant début","✓")))
B11: =IF(C11="","",C11&" · "&D11) | J11: =IF(C11="","",IF(COUNTIF($C$9:$C$38,C11)>1,"⚠ N° en double",IF(AND(F11<>"",G11<>"",G11<F11),"⚠ Fin avant début","✓")))
B12: =IF(C12="","",C12&" · "&D12) | J12: =IF(C12="","",IF(COUNTIF($C$9:$C$38,C12)>1,"⚠ N° en double",IF(AND(F12<>"",G12<>"",G12<F12),"⚠ Fin avant début","✓")))
B13: =IF(C13="","",C13&" · "&D13) | J13: =IF(C13="","",IF(COUNTIF($C$9:$C$38,C13)>1,"⚠ N° en double",IF(AND(F13<>"",G13<>"",G13<F13),"⚠ Fin avant début","✓")))
B14: =IF(C14="","",C14&" · "&D14) | J14: =IF(C14="","",IF(COUNTIF($C$9:$C$38,C14)>1,"⚠ N° en double",IF(AND(F14<>"",G14<>"",G14<F14),"⚠ Fin avant début","✓")))
B15: =IF(C15="","",C15&" · "&D15) | J15: =IF(C15="","",IF(COUNTIF($C$9:$C$38,C15)>1,"⚠ N° en double",IF(AND(F15<>"",G15<>"",G15<F15),"⚠ Fin avant début","✓")))
B16: =IF(C16="","",C16&" · "&D16) | J16: =IF(C16="","",IF(COUNTIF($C$9:$C$38,C16)>1,"⚠ N° en double",IF(AND(F16<>"",G16<>"",G16<F16),"⚠ Fin avant début","✓")))
B17: =IF(C17="","",C17&" · "&D17) | J17: =IF(C17="","",IF(COUNTIF($C$9:$C$38,C17)>1,"⚠ N° en double",IF(AND(F17<>"",G17<>"",G17<F17),"⚠ Fin avant début","✓")))
B18: =IF(C18="","",C18&" · "&D18) | J18: =IF(C18="","",IF(COUNTIF($C$9:$C$38,C18)>1,"⚠ N° en double",IF(AND(F18<>"",G18<>"",G18<F18),"⚠ Fin avant début","✓")))
B19: =IF(C19="","",C19&" · "&D19) | J19: =IF(C19="","",IF(COUNTIF($C$9:$C$38,C19)>1,"⚠ N° en double",IF(AND(F19<>"",G19<>"",G19<F19),"⚠ Fin avant début","✓")))
B20: =IF(C20="","",C20&" · "&D20) | J20: =IF(C20="","",IF(COUNTIF($C$9:$C$38,C20)>1,"⚠ N° en double",IF(AND(F20<>"",G20<>"",G20<F20),"⚠ Fin avant début","✓")))
... B38: =IF(C38="","",C38&" · "&D38) | J38: =IF(C38="","",IF(COUNTIF($C$9:$C$38,C38)>1,"⚠ N° en double",IF(AND(F38<>"",G38<>"",G38<F38),"⚠ Fin avant début","✓")))

Sheet 09 Sous-phases
B2: Sous-phases | J2: =Complétude!$I27 -> 0
B3: Découpage de chaque phase. Numérotation libre, propre au projet et unique : 5.1, 5.2… ou la vôtre. | J3: ↩ Complétude
B4: STRUCTURE Étape 09 Dépend de : Phases
B5: Exemple : phase 5 · Deploy → 5.3 · Répétition générale · 01/09/2026 → 31/03/2027
B7: CALCULÉ | C7: OBLIGATOIRE ▾ | D7: OBLIGATOIRE | E7: OBLIGATOIRE | F7: FACULTATIF | G7: FACULTATIF | H7: FACULTATIF ▾ | I7: FACULTATIF | J7: CONTRÔLE
B8: Clé | C8: Phase | D8: N° | E8: Nom | F8: Début | G8: Fin | H8: Statut | I8: Description | J8: Contrôle
B9: =IF(D9="","",D9&" · "&E9) | J9: =IF(OR(C9="",D9=""),"",IF(COUNTIF($D$9:$D$88,D9)>1,"⚠ N° en double",IF(AND(F9<>"",G9<>"",G9<F9),"⚠ Fin avant début",IF(AND(F9<>"",IFERROR(F9<INDEX('08 Phases'!$F$9:$F$38,MATCH(C9,'08 Phases'!$B$9:$B$38,0)),FALSE)),"◔ Début avant la phase",IF(AND(G9<>"",IFERROR(G9>INDEX('08 Phases'!$G$9:$G$38,MATCH(C9,'08 Phases'!$B$9:$B$38,0)),FALSE)),"◔ Fin après la phase","✓")))))
B10: =IF(D10="","",D10&" · "&E10) | J10: =IF(OR(C10="",D10=""),"",IF(COUNTIF($D$9:$D$88,D10)>1,"⚠ N° en double",IF(AND(F10<>"",G10<>"",G10<F10),"⚠ Fin avant début",IF(AND(F10<>"",IFERROR(F10<INDEX('08 Phases'!$F$9:$F$38,MATCH(C10,'08 Phases'!$B$9:$B$38,0)),FALSE)),"◔ Début avant la phase",IF(AND(G10<>"",IFERROR(G10>INDEX('08 Phases'!$G$9:$G$38,MATCH(C10,'08 Phases'!$B$9:$B$38,0)),FALSE)),"◔ Fin après la phase","✓")))))
B11: =IF(D11="","",D11&" · "&E11) | J11: =IF(OR(C11="",D11=""),"",IF(COUNTIF($D$9:$D$88,D11)>1,"⚠ N° en double",IF(AND(F11<>"",G11<>"",G11<F11),"⚠ Fin avant début",IF(AND(F11<>"",IFERROR(F11<INDEX('08 Phases'!$F$9:$F$38,MATCH(C11,'08 Phases'!$B$9:$B$38,0)),FALSE)),"◔ Début avant la phase",IF(AND(G11<>"",IFERROR(G11>INDEX('08 Phases'!$G$9:$G$38,MATCH(C11,'08 Phases'!$B$9:$B$38,0)),FALSE)),"◔ Fin après la phase","✓")))))
B12: =IF(D12="","",D12&" · "&E12) | J12: =IF(OR(C12="",D12=""),"",IF(COUNTIF($D$9:$D$88,D12)>1,"⚠ N° en double",IF(AND(F12<>"",G12<>"",G12<F12),"⚠ Fin avant début",IF(AND(F12<>"",IFERROR(F12<INDEX('08 Phases'!$F$9:$F$38,MATCH(C12,'08 Phases'!$B$9:$B$38,0)),FALSE)),"◔ Début avant la phase",IF(AND(G12<>"",IFERROR(G12>INDEX('08 Phases'!$G$9:$G$38,MATCH(C12,'08 Phases'!$B$9:$B$38,0)),FALSE)),"◔ Fin après la phase","✓")))))
B13: =IF(D13="","",D13&" · "&E13) | J13: =IF(OR(C13="",D13=""),"",IF(COUNTIF($D$9:$D$88,D13)>1,"⚠ N° en double",IF(AND(F13<>"",G13<>"",G13<F13),"⚠ Fin avant début",IF(AND(F13<>"",IFERROR(F13<INDEX('08 Phases'!$F$9:$F$38,MATCH(C13,'08 Phases'!$B$9:$B$38,0)),FALSE)),"◔ Début avant la phase",IF(AND(G13<>"",IFERROR(G13>INDEX('08 Phases'!$G$9:$G$38,MATCH(C13,'08 Phases'!$B$9:$B$38,0)),FALSE)),"◔ Fin après la phase","✓")))))
B14: =IF(D14="","",D14&" · "&E14) | J14: =IF(OR(C14="",D14=""),"",IF(COUNTIF($D$9:$D$88,D14)>1,"⚠ N° en double",IF(AND(F14<>"",G14<>"",G14<F14),"⚠ Fin avant début",IF(AND(F14<>"",IFERROR(F14<INDEX('08 Phases'!$F$9:$F$38,MATCH(C14,'08 Phases'!$B$9:$B$38,0)),FALSE)),"◔ Début avant la phase",IF(AND(G14<>"",IFERROR(G14>INDEX('08 Phases'!$G$9:$G$38,MATCH(C14,'08 Phases'!$B$9:$B$38,0)),FALSE)),"◔ Fin après la phase","✓")))))
B15: =IF(D15="","",D15&" · "&E15) | J15: =IF(OR(C15="",D15=""),"",IF(COUNTIF($D$9:$D$88,D15)>1,"⚠ N° en double",IF(AND(F15<>"",G15<>"",G15<F15),"⚠ Fin avant début",IF(AND(F15<>"",IFERROR(F15<INDEX('08 Phases'!$F$9:$F$38,MATCH(C15,'08 Phases'!$B$9:$B$38,0)),FALSE)),"◔ Début avant la phase",IF(AND(G15<>"",IFERROR(G15>INDEX('08 Phases'!$G$9:$G$38,MATCH(C15,'08 Phases'!$B$9:$B$38,0)),FALSE)),"◔ Fin après la phase","✓")))))
B16: =IF(D16="","",D16&" · "&E16) | J16: =IF(OR(C16="",D16=""),"",IF(COUNTIF($D$9:$D$88,D16)>1,"⚠ N° en double",IF(AND(F16<>"",G16<>"",G16<F16),"⚠ Fin avant début",IF(AND(F16<>"",IFERROR(F16<INDEX('08 Phases'!$F$9:$F$38,MATCH(C16,'08 Phases'!$B$9:$B$38,0)),FALSE)),"◔ Début avant la phase",IF(AND(G16<>"",IFERROR(G16>INDEX('08 Phases'!$G$9:$G$38,MATCH(C16,'08 Phases'!$B$9:$B$38,0)),FALSE)),"◔ Fin après la phase","✓")))))
B17: =IF(D17="","",D17&" · "&E17) | J17: =IF(OR(C17="",D17=""),"",IF(COUNTIF($D$9:$D$88,D17)>1,"⚠ N° en double",IF(AND(F17<>"",G17<>"",G17<F17),"⚠ Fin avant début",IF(AND(F17<>"",IFERROR(F17<INDEX('08 Phases'!$F$9:$F$38,MATCH(C17,'08 Phases'!$B$9:$B$38,0)),FALSE)),"◔ Début avant la phase",IF(AND(G17<>"",IFERROR(G17>INDEX('08 Phases'!$G$9:$G$38,MATCH(C17,'08 Phases'!$B$9:$B$38,0)),FALSE)),"◔ Fin après la phase","✓")))))
B18: =IF(D18="","",D18&" · "&E18) | J18: =IF(OR(C18="",D18=""),"",IF(COUNTIF($D$9:$D$88,D18)>1,"⚠ N° en double",IF(AND(F18<>"",G18<>"",G18<F18),"⚠ Fin avant début",IF(AND(F18<>"",IFERROR(F18<INDEX('08 Phases'!$F$9:$F$38,MATCH(C18,'08 Phases'!$B$9:$B$38,0)),FALSE)),"◔ Début avant la phase",IF(AND(G18<>"",IFERROR(G18>INDEX('08 Phases'!$G$9:$G$38,MATCH(C18,'08 Phases'!$B$9:$B$38,0)),FALSE)),"◔ Fin après la phase","✓")))))
B19: =IF(D19="","",D19&" · "&E19) | J19: =IF(OR(C19="",D19=""),"",IF(COUNTIF($D$9:$D$88,D19)>1,"⚠ N° en double",IF(AND(F19<>"",G19<>"",G19<F19),"⚠ Fin avant début",IF(AND(F19<>"",IFERROR(F19<INDEX('08 Phases'!$F$9:$F$38,MATCH(C19,'08 Phases'!$B$9:$B$38,0)),FALSE)),"◔ Début avant la phase",IF(AND(G19<>"",IFERROR(G19>INDEX('08 Phases'!$G$9:$G$38,MATCH(C19,'08 Phases'!$B$9:$B$38,0)),FALSE)),"◔ Fin après la phase","✓")))))
B20: =IF(D20="","",D20&" · "&E20) | J20: =IF(OR(C20="",D20=""),"",IF(COUNTIF($D$9:$D$88,D20)>1,"⚠ N° en double",IF(AND(F20<>"",G20<>"",G20<F20),"⚠ Fin avant début",IF(AND(F20<>"",IFERROR(F20<INDEX('08 Phases'!$F$9:$F$38,MATCH(C20,'08 Phases'!$B$9:$B$38,0)),FALSE)),"◔ Début avant la phase",IF(AND(G20<>"",IFERROR(G20>INDEX('08 Phases'!$G$9:$G$38,MATCH(C20,'08 Phases'!$B$9:$B$38,0)),FALSE)),"◔ Fin après la phase","✓")))))
... B88: =IF(D88="","",D88&" · "&E88) | J88: =IF(OR(C88="",D88=""),"",IF(COUNTIF($D$9:$D$88,D88)>1,"⚠ N° en double",IF(AND(F88<>"",G88<>"",G88<F88),"⚠ Fin avant début",IF(AND(F88<>"",IFERROR(F88<INDEX('08 Phases'!$F$9:$F$38,MATCH(C88,'08 Phases'!$B$9:$B$38,0)),FALSE)),"◔ Début avant la phase",IF(AND(G88<>"",IFERROR(G88>INDEX('08 Phases'!$G$9:$G$38,MATCH(C88,'08 Phases'!$B$9:$B$38,0)),FALSE)),"◔ Fin après la phase","✓")))))

Sheet 10 Chantiers
B2: Chantiers | M2: =Complétude!$I28 -> 0
B3: Domaines de travail transverses aux phases (Finance, Migration…). Un responsable par chantier. Début et fin : facultatifs, calculés sinon à partir des sous-phases du chantier. Phases, sous-phases et dépendances : plusieurs valeurs séparées par « ; ». | M3: ↩ Complétude
B4: STRUCTURE Étape 10 Dépend de : Personnes, Lots, Phases, Sous-phases
B5: Exemple : C5 · Migration des données · Karim Benali · Lot 1 · Actif · 01/03/2027 → 31/10/2027 · 3 ; 4 · 3.1 ; 4.2 · Finance ; Achats
B7: CALCULÉ | C7: OBLIGATOIRE | D7: OBLIGATOIRE ▾ | E7: FACULTATIF ▾ | F7: FACULTATIF ▾ | G7: FACULTATIF | H7: FACULTATIF | I7: FACULTATIF | J7: FACULTATIF ; | K7: FACULTATIF ; | L7: FACULTATIF ; | M7: CONTRÔLE
B8: Code | C8: Nom | D8: Responsable | E8: Lot | F8: Statut | G8: Début | H8: Fin | I8: Description | J8: Phases | K8: Sous-phases | L8: Dépendances | M8: Contrôle
B9: =IF(C9="","","C"&(ROW()-8)) | M9: =IF(C9="","",IF(AND(L9<>"",ISNUMBER(SEARCH(";"&C9&";",";"&SUBSTITUTE(SUBSTITUTE(TRIM(L9)," ;",";"),"; ",";")&";"))),"⚠ Dépend de lui-même",IF(AND(ISNUMBER(SEARCH(";Tous;",";"&SUBSTITUTE(SUBSTITUTE(TRIM(L9)," ;",";"),"; ",";")&";")),LEN(";"&SUBSTITUTE(SUBSTITUTE(TRIM(L9)," ;",";"),"; ",";")&";")>6),"⚠ « Tous » seul",IF(AND(K9<>"",J9=""),"⚠ Sous-phases sans phase","✓"))))
B10: =IF(C10="","","C"&(ROW()-8)) | M10: =IF(C10="","",IF(AND(L10<>"",ISNUMBER(SEARCH(";"&C10&";",";"&SUBSTITUTE(SUBSTITUTE(TRIM(L10)," ;",";"),"; ",";")&";"))),"⚠ Dépend de lui-même",IF(AND(ISNUMBER(SEARCH(";Tous;",";"&SUBSTITUTE(SUBSTITUTE(TRIM(L10)," ;",";"),"; ",";")&";")),LEN(";"&SUBSTITUTE(SUBSTITUTE(TRIM(L10)," ;",";"),"; ",";")&";")>6),"⚠ « Tous » seul",IF(AND(K10<>"",J10=""),"⚠ Sous-phases sans phase","✓"))))
B11: =IF(C11="","","C"&(ROW()-8)) | M11: =IF(C11="","",IF(AND(L11<>"",ISNUMBER(SEARCH(";"&C11&";",";"&SUBSTITUTE(SUBSTITUTE(TRIM(L11)," ;",";"),"; ",";")&";"))),"⚠ Dépend de lui-même",IF(AND(ISNUMBER(SEARCH(";Tous;",";"&SUBSTITUTE(SUBSTITUTE(TRIM(L11)," ;",";"),"; ",";")&";")),LEN(";"&SUBSTITUTE(SUBSTITUTE(TRIM(L11)," ;",";"),"; ",";")&";")>6),"⚠ « Tous » seul",IF(AND(K11<>"",J11=""),"⚠ Sous-phases sans phase","✓"))))
